Workbook

Sheet Summary
A1: Spain 2027 plan summary
A2: Today | B2: =TODAY()
A4: Deadlines: open items by workstream
A5: Workstream | B5: Open | C5: Overdue | D5: Due in 14 days | E5: Done
A6: Programs | B6: =COUNTIFS(Deadlines!$B$2:$B$34,A6,Deadlines!$E$2:$E$34,"<>Done") | C6: =COUNTIFS(Deadlines!$B$2:$B$34,A6,Deadlines!$E$2:$E$34,"<>Done",Deadlines!$C$2:$C$34,"<"&TODAY()) | D6: =COUNTIFS(Deadlines!$B$2:$B$34,A6,Deadlines!$E$2:$E$34,"<>Done",Deadlines!$C$2:$C$34,">="&TODAY(),Deadlines!$C$2:$C$34,"<="&(TODAY()+14)) | E6: =COUNTIFS(Deadlines!$B$2:$B$34,A6,Deadlines!$E$2:$E$34,"Done")
A7: Immigration | B7: =COUNTIFS(Deadlines!$B$2:$B$34,A7,Deadlines!$E$2:$E$34,"<>Done") | C7: =COUNTIFS(Deadlines!$B$2:$B$34,A7,Deadlines!$E$2:$E$34,"<>Done",Deadlines!$C$2:$C$34,"<"&TODAY()) | D7: =COUNTIFS(Deadlines!$B$2:$B$34,A7,Deadlines!$E$2:$E$34,"<>Done",Deadlines!$C$2:$C$34,">="&TODAY(),Deadlines!$C$2:$C$34,"<="&(TODAY()+14)) | E7: =COUNTIFS(Deadlines!$B$2:$B$34,A7,Deadlines!$E$2:$E$34,"Done")
A8: Tax | B8: =COUNTIFS(Deadlines!$B$2:$B$34,A8,Deadlines!$E$2:$E$34,"<>Done") | C8: =COUNTIFS(Deadlines!$B$2:$B$34,A8,Deadlines!$E$2:$E$34,"<>Done",Deadlines!$C$2:$C$34,"<"&TODAY()) | D8: =COUNTIFS(Deadlines!$B$2:$B$34,A8,Deadlines!$E$2:$E$34,"<>Done",Deadlines!$C$2:$C$34,">="&TODAY(),Deadlines!$C$2:$C$34,"<="&(TODAY()+14)) | E8: =COUNTIFS(Deadlines!$B$2:$B$34,A8,Deadlines!$E$2:$E$34,"Done")
A9: Income | B9: =COUNTIFS(Deadlines!$B$2:$B$34,A9,Deadlines!$E$2:$E$34,"<>Done") | C9: =COUNTIFS(Deadlines!$B$2:$B$34,A9,Deadlines!$E$2:$E$34,"<>Done",Deadlines!$C$2:$C$34,"<"&TODAY()) | D9: =COUNTIFS(Deadlines!$B$2:$B$34,A9,Deadlines!$E$2:$E$34,"<>Done",Deadlines!$C$2:$C$34,">="&TODAY(),Deadlines!$C$2:$C$34,"<="&(TODAY()+14)) | E9: =COUNTIFS(Deadlines!$B$2:$B$34,A9,Deadlines!$E$2:$E$34,"Done")
A10: Trip | B10: =COUNTIFS(Deadlines!$B$2:$B$34,A10,Deadlines!$E$2:$E$34,"<>Done") | C10: =COUNTIFS(Deadlines!$B$2:$B$34,A10,Deadlines!$E$2:$E$34,"<>Done",Deadlines!$C$2:$C$34,"<"&TODAY()) | D10: =COUNTIFS(Deadlines!$B$2:$B$34,A10,Deadlines!$E$2:$E$34,"<>Done",Deadlines!$C$2:$C$34,">="&TODAY(),Deadlines!$C$2:$C$34,"<="&(TODAY()+14)) | E10: =COUNTIFS(Deadlines!$B$2:$B$34,A10,Deadlines!$E$2:$E$34,"Done")
A11: Outreach | B11: =COUNTIFS(Deadlines!$B$2:$B$34,A11,Deadlines!$E$2:$E$34,"<>Done") | C11: =COUNTIFS(Deadlines!$B$2:$B$34,A11,Deadlines!$E$2:$E$34,"<>Done",Deadlines!$C$2:$C$34,"<"&TODAY()) | D11: =COUNTIFS(Deadlines!$B$2:$B$34,A11,Deadlines!$E$2:$E$34,"<>Done",Deadlines!$C$2:$C$34,">="&TODAY(),Deadlines!$C$2:$C$34,"<="&(TODAY()+14)) | E11: =COUNTIFS(Deadlines!$B$2:$B$34,A11,Deadlines!$E$2:$E$34,"Done")
A12: Kindergarten | B12: =COUNTIFS(Deadlines!$B$2:$B$34,A12,Deadlines!$E$2:$E$34,"<>Done") | C12: =COUNTIFS(Deadlines!$B$2:$B$34,A12,Deadlines!$E$2:$E$34,"<>Done",Deadlines!$C$2:$C$34,"<"&TODAY()) | D12: =COUNTIFS(Deadlines!$B$2:$B$34,A12,Deadlines!$E$2:$E$34,"<>Done",Deadlines!$C$2:$C$34,">="&TODAY(),Deadlines!$C$2:$C$34,"<="&(TODAY()+14)) | E12: =COUNTIFS(Deadlines!$B$2:$B$34,A12,Deadlines!$E$2:$E$34,"Done")
A13: Spanish | B13: =COUNTIFS(Deadlines!$B$2:$B$34,A13,Deadlines!$E$2:$E$34,"<>Done") | C13: =COUNTIFS(Deadlines!$B$2:$B$34,A13,Deadlines!$E$2:$E$34,"<>Done",Deadlines!$C$2:$C$34,"<"&TODAY()) | D13: =COUNTIFS(Deadlines!$B$2:$B$34,A13,Deadlines!$E$2:$E$34,"<>Done",Deadlines!$C$2:$C$34,">="&TODAY(),Deadlines!$C$2:$C$34,"<="&(TODAY()+14)) | E13: =COUNTIFS(Deadlines!$B$2:$B$34,A13,Deadlines!$E$2:$E$34,"Done")
A14: Move | B14: =COUNTIFS(Deadlines!$B$2:$B$34,A14,Deadlines!$E$2:$E$34,"<>Done") | C14: =COUNTIFS(Deadlines!$B$2:$B$34,A14,Deadlines!$E$2:$E$34,"<>Done",Deadlines!$C$2:$C$34,"<"&TODAY()) | D14: =COUNTIFS(Deadlines!$B$2:$B$34,A14,Deadlines!$E$2:$E$34,"<>Done",Deadlines!$C$2:$C$34,">="&TODAY(),Deadlines!$C$2:$C$34,"<="&(TODAY()+14)) | E14: =COUNTIFS(Deadlines!$B$2:$B$34,A14,Deadlines!$E$2:$E$34,"Done")
A15: Housing | B15: =COUNTIFS(Deadlines!$B$2:$B$34,A15,Deadlines!$E$2:$E$34,"<>Done") | C15: =COUNTIFS(Deadlines!$B$2:$B$34,A15,Deadlines!$E$2:$E$34,"<>Done",Deadlines!$C$2:$C$34,"<"&TODAY()) | D15: =COUNTIFS(Deadlines!$B$2:$B$34,A15,Deadlines!$E$2:$E$34,"<>Done",Deadlines!$C$2:$C$34,">="&TODAY(),Deadlines!$C$2:$C$34,"<="&(TODAY()+14)) | E15: =COUNTIFS(Deadlines!$B$2:$B$34,A15,Deadlines!$E$2:$E$34,"Done")
A16: Work | B16: =COUNTIFS(Deadlines!$B$2:$B$34,A16,Deadlines!$E$2:$E$34,"<>Done") | C16: =COUNTIFS(Deadlines!$B$2:$B$34,A16,Deadlines!$E$2:$E$34,"<>Done",Deadlines!$C$2:$C$34,"<"&TODAY()) | D16: =COUNTIFS(Deadlines!$B$2:$B$34,A16,Deadlines!$E$2:$E$34,"<>Done",Deadlines!$C$2:$C$34,">="&TODAY(),Deadlines!$C$2:$C$34,"<="&(TODAY()+14)) | E16: =COUNTIFS(Deadlines!$B$2:$B$34,A16,Deadlines!$E$2:$E$34,"Done")
A17: Dog | B17: =COUNTIFS(Deadlines!$B$2:$B$34,A17,Deadlines!$E$2:$E$34,"<>Done") | C17: =COUNTIFS(Deadlines!$B$2:$B$34,A17,Deadlines!$E$2:$E$34,"<>Done",Deadlines!$C$2:$C$34,"<"&TODAY()) | D17: =COUNTIFS(Deadlines!$B$2:$B$34,A17,Deadlines!$E$2:$E$34,"<>Done",Deadlines!$C$2:$C$34,">="&TODAY(),Deadlines!$C$2:$C$34,"<="&(TODAY()+14)) | E17: =COUNTIFS(Deadlines!$B$2:$B$34,A17,Deadlines!$E$2:$E$34,"Done")
A18: Total | B18: =SUM(B6:B17) | C18: =SUM(C6:C17) | D18: =SUM(D6:D17) | E18: =SUM(E6:E17)
A20: Monthly actions: open items by month
A21: Month | B21: Open | C21: Done
A22: 46266 | B22: =COUNTIFS('Monthly actions'!$A$2:$A$90,A22,'Monthly actions'!$E$2:$E$90,"<>Done") | C22: =COUNTIFS('Monthly actions'!$A$2:$A$90,A22,'Monthly actions'!$E$2:$E$90,"Done")
A23: 46296 | B23: =COUNTIFS('Monthly actions'!$A$2:$A$90,A23,'Monthly actions'!$E$2:$E$90,"<>Done") | C23: =COUNTIFS('Monthly actions'!$A$2:$A$90,A23,'Monthly actions'!$E$2:$E$90,"Done")
A24: 46327 | B24: =COUNTIFS('Monthly actions'!$A$2:$A$90,A24,'Monthly actions'!$E$2:$E$90,"<>Done") | C24: =COUNTIFS('Monthly actions'!$A$2:$A$90,A24,'Monthly actions'!$E$2:$E$90,"Done")
A25: 46357 | B25: =COUNTIFS('Monthly actions'!$A$2:$A$90,A25,'Monthly actions'!$E$2:$E$90,"<>Done") | C25: =COUNTIFS('Monthly actions'!$A$2:$A$90,A25,'Monthly actions'!$E$2:$E$90,"Done")
A26: 46388 | B26: =COUNTIFS('Monthly actions'!$A$2:$A$90,A26,'Monthly actions'!$E$2:$E$90,"<>Done") | C26: =COUNTIFS('Monthly actions'!$A$2:$A$90,A26,'Monthly actions'!$E$2:$E$90,"Done")
A27: 46419 | B27: =COUNTIFS('Monthly actions'!$A$2:$A$90,A27,'Monthly actions'!$E$2:$E$90,"<>Done") | C27: =COUNTIFS('Monthly actions'!$A$2:$A$90,A27,'Monthly actions'!$E$2:$E$90,"Done")
A28: 46447 | B28: =COUNTIFS('Monthly actions'!$A$2:$A$90,A28,'Monthly actions'!$E$2:$E$90,"<>Done") | C28: =COUNTIFS('Monthly actions'!$A$2:$A$90,A28,'Monthly actions'!$E$2:$E$90,"Done")
A29: 46478 | B29: =COUNTIFS('Monthly actions'!$A$2:$A$90,A29,'Monthly actions'!$E$2:$E$90,"<>Done") | C29: =COUNTIFS('Monthly actions'!$A$2:$A$90,A29,'Monthly actions'!$E$2:$E$90,"Done")
A30: 46508 | B30: =COUNTIFS('Monthly actions'!$A$2:$A$90,A30,'Monthly actions'!$E$2:$E$90,"<>Done") | C30: =COUNTIFS('Monthly actions'!$A$2:$A$90,A30,'Monthly actions'!$E$2:$E$90,"Done")
A31: 46539 | B31: =COUNTIFS('Monthly actions'!$A$2:$A$90,A31,'Monthly actions'!$E$2:$E$90,"<>Done") | C31: =COUNTIFS('Monthly actions'!$A$2:$A$90,A31,'Monthly actions'!$E$2:$E$90,"Done")
A32: 46569 | B32: =COUNTIFS('Monthly actions'!$A$2:$A$90,A32,'Monthly actions'!$E$2:$E$90,"<>Done") | C32: =COUNTIFS('Monthly actions'!$A$2:$A$90,A32,'Monthly actions'!$E$2:$E$90,"Done")
A33: 46600 | B33: =COUNTIFS('Monthly actions'!$A$2:$A$90,A33,'Monthly actions'!$E$2:$E$90,"<>Done") | C33: =COUNTIFS('Monthly actions'!$A$2:$A$90,A33,'Monthly actions'!$E$2:$E$90,"Done")
... A35: 46661 | B35: =COUNTIFS('Monthly actions'!$A$2:$A$90,A35,'Monthly actions'!$E$2:$E$90,"<>Done") | C35: =COUNTIFS('Monthly actions'!$A$2:$A$90,A35,'Monthly actions'!$E$2:$E$90,"Done")

Sheet Deadlines
A1: Task | B1: Workstream | C1: Due | D1: Days left | E1: Status | F1: Type | G1: Confidence | H1: Source, checked | I1: Notes
A2: ELISAVA Design for Responsible AI, 2026 intake application deadline (past) | B2: Programs | C2: 46273 | D2: =IF(OR(C2="",E2="Done"),"",C2-TODAY()) | E2: Done | F2: EXTERNAL | G2: confirmed | H2: User, 2026-09-09
A3: Client and contract inventory complete with end dates and monthly value | B3: Income | C3: 46295 | D3: =IF(OR(C3="",E3="Done"),"",C3-TODAY()) | E3: Not started | F3: TARGET | G3: assumed | H3: This plan
A4: October trip dates fixed and flights booked | B4: Trip | C4: 46295 | D4: =IF(OR(C4="",E4="Done"),"",C4-TODAY()) | E4: Not started | F4: TARGET | G4: assumed | H4: This plan
A5: Verify which Spanish consulate covers Colorado | B5: Immigration | C5: 46295 | D5: =IF(OR(C5="",E5="Done"),"",C5-TODAY()) | E5: Not started | F5: TARGET | G5: assumed | H5: This plan
A6: Income evidence window opens: every month from here to filing must show consistent deposits at or above threshold | B6: Income | C6: 46296 | D6: =IF(OR(C6="",E6="Done"),"",C6-TODAY()) | E6: Not started | F6: RELATIVE | G6: assumed | H6: Chat 1: 3 to 6 months before filing
A7: Outreach sent to Salesforce partners in Barcelona, meetings requested for trip | B7: Outreach | C7: 46310 | D7: =IF(OR(C7="",E7="Done"),"",C7-TODAY()) | E7: Not started | F7: TARGET | G7: assumed | H7: This plan
A8: New EU pet certificate forms take effect; any dog travel after this date uses the new forms | B8: Move | C8: 46296 | D8: =IF(OR(C8="",E8="Done"),"",C8-TODAY()) | E8: Info | F8: EXTERNAL | G8: confirmed | H8: APHIS via search, 2026-09-09
A9: EU Business School Barcelona open day, 16:00 to 18:00 | B9: Programs | C9: 46318 | D9: =IF(OR(C9="",E9="Done"),"",C9-TODAY()) | E9: Not started | F9: EXTERNAL | G9: confirmed | H9: euruni.edu events page via search, 2026-09-09
A10: Barcelona trip: neighborhood, schools, kindergartens, agencies, partner meetings | B10: Trip | C10: 46296 | D10: =IF(OR(C10="",E10="Done"),"",C10-TODAY()) | E10: Not started | F10: TARGET | G10: assumed | H10: User, 2026-09-09 | I10: Month only. dates TBD
A11: Spanish milestone: Language Transfer complete, 1200 words, 20-minute tutor conversation | B11: Spanish | C11: 46326 | D11: =IF(OR(C11="",E11="Done"),"",C11-TODAY()) | E11: Not started | F11: TARGET | G11: confirmed | H11: Spanish plan
A12: All shortlisted programs contacted; 2027 intake status and deadline recorded | B12: Programs | C12: 46326 | D12: =IF(OR(C12="",E12="Done"),"",C12-TODAY()) | E12: Not started | F12: TARGET | G12: assumed | H12: This plan
A13: Tax advisor consult done; Beckham path decided (administrator route or standard autonomo) | B13: Tax | C13: 46341 | D13: =IF(OR(C13="",E13="Done"),"",C13-TODAY()) | E13: Not started | F13: TARGET | G13: assumed | H13: This plan
A14: If administrator route: LLC operating agreement amended | B14: Tax | C14: 46356 | D14: =IF(OR(C14="",E14="Done"),"",C14-TODAY()) | E14: Not started | F14: TARGET | G14: assumed | H14: Chat 1
A15: TBS Education Barcelona MSc application deadline for 2027 intake (2026 intake closed 2025-12-12) | B15: Programs | C15: 46357 | D15: =IF(OR(C15="",E15="Done"),"",C15-TODAY()) | E15: Not started | F15: EXTERNAL | G15: assumed | H15: Search snippet, 2026-09-09 | I15: Month only. assumed
A16: Contracts signed covering at least Jan to Dec 2027 at or above threshold | B16: Income | C16: 46371 | D16: =IF(OR(C16="",E16="Done"),"",C16-TODAY()) | E16: Not started | F16: TARGET | G16: assumed | H16: This plan
A17: Health insurance policy selected | B17: Immigration | C17: 46387 | D17: =IF(OR(C17="",E17="Done"),"",C17-TODAY()) | E17: Not started | F17: TARGET | G17: assumed | H17: This plan
A18: FBI background check ordered | B18: Immigration | C18: 46387 | D18: =IF(OR(C18="",E18="Done"),"",C18-TODAY()) | E18: Not started | F18: TARGET | G18: assumed | H18: Chat 2
A19: Spanish milestone: 2500 words, can handle landlord or bank call | B19: Spanish | C19: 46418 | D19: =IF(OR(C19="",E19="Done"),"",C19-TODAY()) | E19: Not started | F19: TARGET | G19: confirmed | H19: Spanish plan
A20: Apostille chain started for all documents | B20: Immigration | C20: 46418 | D20: =IF(OR(C20="",E20="Done"),"",C20-TODAY()) | E20: Not started | F20: TARGET | G20: assumed | H20: Chat 1
A21: Catalonia school preinscripcio 2027-28 for I3 to I5; 2026-27 window was March 4 to 18. Late filing loses priority points | B21: Kindergarten | C21: 46447 | D21: =IF(OR(C21="",E21="Done"),"",C21-TODAY()) | E21: Not started | F21: EXTERNAL | G21: assumed | H21: preinscripcio.gencat.cat via search, 2026-09-09 | I21: Month only. early, assumed
A22: Sworn translations ordered | B22: Immigration | C22: 46461 | D22: =IF(OR(C22="",E22="Done"),"",C22-TODAY()) | E22: Not started | F22: TARGET | G22: assumed | H22: Chat 1
A23: Visa packet complete | B23: Immigration | C23: 46477 | D23: =IF(OR(C23="",E23="Done"),"",C23-TODAY()) | E23: Not started | F23: TARGET | G23: assumed | H23: Chat 1
A24: DNV filed (consular EX-01) or in-country plan locked | B24: Immigration | C24: 46492 | D24: =IF(OR(C24="",E24="Done"),"",C24-TODAY()) | E24: Not started | F24: TARGET | G24: assumed | H24: Chat 1
A25: Spanish milestone: B1, unstructured conversation without English | B25: Spanish | C25: 46507 | D25: =IF(OR(C25="",E25="Done"),"",C25-TODAY()) | E25: Not started | F25: TARGET | G25: confirmed | H25: Spanish plan
A26: BTS Master in Digital Transformation and AI Leadership deadline for September 2027 intake | B26: Programs | C26: 46539 | D26: =IF(OR(C26="",E26="Done"),"",C26-TODAY()) | E26: Not started | F26: EXTERNAL | G26: assumed | H26: Aggregator, 2026-09-09 | I26: Month only. assumed
A27: Arrival in Barcelona | B27: Move | C27: 46508 | D27: =IF(OR(C27="",E27="Done"),"",C27-TODAY()) | E27: Not started | F27: TARGET | G27: assumed | H27: User | I27: Month only. date TBD
A28: Dog EU health certificate issued | B28: Move | D28: =IF(OR(C28="",E28="Done"),"",C28-TODAY()) | E28: Not started | F28: RELATIVE | G28: confirmed | H28: Chat 2 | I28: Arrival minus 10 days
A29: Empadronamiento registered | B29: Move | D29: =IF(OR(C29="",E29="Done"),"",C29-TODAY()) | E29: Not started | F29: RELATIVE | G29: assumed | H29: Chat 3 | I29: Arrival plus 30 days
A30: If in-country EX-11 route: must file within 90 days of visa-free entry | B30: Immigration | D30: =IF(OR(C30="",E30="Done"),"",C30-TODAY()) | E30: Not started | F30: RELATIVE | G30: confirmed | H30: Chat 1 | I30: Arrival plus 90 days
A31: Modelo 149 (Beckham) filed, only if eligible | B31: Tax | D31: =IF(OR(C31="",E31="Done"),"",C31-TODAY()) | E31: Not started | F31: RELATIVE | G31: confirmed | H31: Chat 1 | I31: SS registration plus 6 months
A32: ELISAVA 2027 intake application deadline | B32: Programs | C32: 46638 | D32: =IF(OR(C32="",E32="Done"),"",C32-TODAY()) | E32: Not started | F32: EXTERNAL | G32: assumed, same as 2026 | H32: User, 2026-09-09
A33: Program start | B33: Programs | C33: 46631 | D33: =IF(OR(C33="",E33="Done"),"",C33-TODAY()) | E33: Not started | F33: EXTERNAL | G33: not verified | I33: Month only. or 2027-10
A34: DNV renewal; income re-proven over prior 3 to 6 months | B34: Immigration | D34: =IF(OR(C34="",E34="Done"),"",C34-TODAY()) | E34: Not started | F34: RELATIVE | G34: confirmed | H34: Chat 1 | I34: Filing plus 1 year (consular) or 3 years (in-country)

Sheet Monthly actions
A1: Month | B1: Workstream | C1: Action | D1: Due | E1: Status | F1: Notes
A2: 46266 | B2: Income | C2: Inventory every current client: contract end date, monthly value, entity type, country. | D2: 46295 | E2: Not started
A3: 46266 | B3: Income | C3: Gap analysis Oct 2026 to Dec 2027 against 5,400 to 5,900 USD per month. | D3: 46295 | E3: Not started
A4: 46266 | B4: Income | C4: Route all client deposits to one business account; invoice monthly. | D4: 46296 | E4: Not started
A5: 46266 | B5: Programs | C5: Record ELISAVA's answer: 2027 intake not confirmed (received 2026-09-09). | E5: Not started
A6: 46266 | B6: Programs | C6: Email the seven new schools (BTS, TBS, EAE Barcelona, ESIC, IED, La Salle MSc, Comillas) for: 2027 intake deadline, syllabus with coding content, language, schedule, degree type, tuition. | D6: 46295 | E6: Not started
A7: 46266 | B7: Programs | C7: Verify each answer against the hard rules and move the program to shortlisted or eliminated. | E7: Not started
A8: 46266 | B8: Trip | C8: Fix dates and book flights. | D8: 46295 | E8: Not started
A9: 46266 | B9: Trip | C9: Book accommodation in a candidate neighborhood. | D9: 46295 | E9: Not started
A10: 46266 | B10: Trip | C10: Request admissions meetings. | D10: 46295 | E10: Not started
A11: 46266 | B11: Immigration | C11: Verify which consulate covers Colorado. | D11: 46295 | E11: Not started
A12: 46266 | B12: Immigration | C12: Book NIE appointment; prepare EX-15, passport copy, fee 790-012. | E12: Not started
A13: 46266 | B13: Immigration | C13: Check all three passports valid to at least May 2028. | E13: Not started
A14: 46266 | B14: Immigration | C14: Pull LLC documents: articles, operating agreement, 3 to 6 months statements, contracts, invoices. | E14: Not started
A15: 46266 | B15: Immigration | C15: Request health insurance quotes (full coverage, no copays, no waiting period). | E15: Not started
A16: 46266 | B16: Tax | C16: Book the Spanish cross-border tax advisor consult (Beckham for LLC owner). | E16: Not started
A17: 46266 | B17: Spanish | C17: Daily template. Start tutoring by week 3 of the plan if not started. | E17: Not started
A18: 46266 | B18: Dog | C18: Vet: confirm microchip and rabies vaccine current. | E18: Not started
A19: 46296 | B19: Income | C19: Evidence window opens 10-01: every month from now must show deposits at or above threshold. | E19: Not started
A20: 46296 | B20: Income | C20: Pipeline list of retainer prospects. | D20: 46310 | E20: Not started
A21: 46296 | B21: Income | C21: Send retainer or extension proposals. | D21: 46326 | E21: Not started
A22: 46296 | B22: Income | C22: Ask the bank how to get stamped statements. | D22: 46326 | E22: Not started
A23: 46296 | B23: Income | C23: Log October deposits in the evidence log. | E23: Not started
A24: 46296 | B24: Outreach | C24: Send Salesforce partner outreach. | D24: 46310 | E24: Not started
A25: 46296 | B25: Outreach | C25: Hold partner meetings during the trip. Log outcomes. | E25: Not started
A26: 46296 | B26: Kindergarten | C26: Record the daughter's birth date and 2027 school year. | D26: 46295 | E26: Not started
A27: 46296 | B27: Kindergarten | C27: Ask the Consorci d'Educacio whether the March 2027 preinscripcio can be filed from abroad. | D27: 46326 | E27: Not started
A28: 46296 | B28: Trip | C28: EU Business School open day October 23, 16:00 to 18:00, if dates align. | E28: Not started
A29: 46296 | B29: Trip | C29: Kindergarten and school visits requested. | D29: 46300 | E29: Not started
A30: 46296 | B30: Trip | C30: Agency and lawyer meetings requested. | D30: 46300 | E30: Not started
A31: 46296 | B31: Trip | C31: Itinerary and question lists. Trip minus 7 days. | E31: Not started
A32: 46296 | B32: Trip | C32: Trip: neighborhood decision, university visits, kindergarten visits, agency meetings, partner meetings. | E32: Not started
A33: 46296 | B33: Trip | C33: After the trip: write up decisions in plan/trip/october-2026-barcelona.md and update profile.md. | E33: Not started
A34: 46296 | B34: Programs | C34: All shortlisted programs contacted; 2027 intake status and deadlines recorded. | D34: 46326 | E34: Not started
A35: 46296 | B35: Programs | C35: Start shared application assets: CV, diploma and transcript scans, passport scan. | E35: Not started
A36: 46296 | B36: Spanish | C36: Milestone 10-31: Language Transfer done, 1200 words, 20-minute tutor conversation. | E36: Not started
A37: 46327 | B37: Income | C37: Follow up on every open proposal. Log November deposits. | E37: Not started
A38: 46327 | B38: Tax | C38: Tax advisor consult done; Beckham path decided. | D38: 46341 | E38: Not started
A39: 46327 | B39: Tax | C39: If administrator route: amend LLC operating agreement. | D39: 46356 | E39: Not started
A40: 46327 | B40: Programs | C40: Draft one motivation letter per program in plan/documents/. | E40: Not started
...

Sheet Programs
A1: Program | B1: University | C1: City | D1: Status | E1: Deadline | F1: Missing items | G1: Last checked
A2: Master in Design for Responsible AI | B2: ELISAVA (UVic-UCC) | C2: Barcelona | D2: Applying. Primary target. School not yet committed to running a Sept 2027 intake. | E2: Not verified | F2: Confirm 2027 intake runs; deadline; motivation letter; meeting in Oct 2026 | G2: 2026-09-08
A3: Master in AI for Business | B3: EU Business School | C3: Barcelona | D3: Shortlisted, apply | E3: Not verified | F3: Deadline; syllabus re-check; meeting in Oct 2026 | G3: 2026-09-08
A4: Master in AI for Management | B4: GBSB Global | C4: Barcelona | D4: Shortlisted with conflict, see program file | E4: Not verified | F4: Resolve credential conflict; verify analytics modules are no-code; meeting in Oct 2026 | G4: 2026-09-08
A5: Master in Public Policy, AI and Digital Transformation | B5: IE University | C5: Madrid | D5: Shortlisted with conflict, see program file | E5: Not verified | F5: User decision: public policy was ruled out on 2026-08-07 | G5: 2026-09-08
A6: Expert Diploma in Responsible Management of AI | B6: UPF-BSM | C6: Barcelona | D6: Meeting only, not a master | E6: Not verified | F6: Book meeting in Oct 2026 | G6: 2026-09-08
A7: Master in Digital Transformation and AI Leadership | B7: Barcelona Technology School | C7: Barcelona | D7: New, to verify | E7: Not published; about June 2027 assumed | F7: Syllabus, degree type, schedule, deadline; meeting in Oct 2026 | G7: 2026-09-09
A8: MSc Digital Transformation and AI for Business | B8: TBS Education | C8: Barcelona | D8: New, to verify | E8: Not published; about Dec 2026 assumed from 2025-12-12 | F8: Senior fit, schedule, internship, deadline; meeting in Oct 2026 | G8: 2026-09-09
A9: Master en IA Aplicada a Negocio | B9: EAE Business School | C9: Barcelona | D9: New, coding and language unresolved | E9: Not published | F9: Syllabus, language, official status, deadline | G9: 2026-09-09
A10: Master en Inteligencia Artificial (MIA) | B10: ESIC | C10: Barcelona | D10: New, coding unresolved | E10: Not published | F10: Syllabus, language, deadline | G10: 2026-09-09
A11: Master in Design for AI | B11: IED Barcelona | C11: Barcelona | D11: New, to verify | E11: Not published | F11: Syllabus, coding, language, schedule, deadline; meeting in Oct 2026 | G11: 2026-09-09
A12: MSc AI for Business Management | B12: La Salle (URL) | C12: Barcelona | D12: New, coding unresolved | E12: Not published | F12: Syllabus, coding, schedule, deadline | G12: 2026-09-09
A13: Master en Filosofia de la IA | B13: Comillas | C13: Madrid | D13: New, Madrid only | E13: Not published | F13: Format, language, official status, deadline | G13: 2026-09-09

Sheet Income log
A1: Threshold EUR per month (2026 basis, family of three) | B1: 4275
A2: Exchange buffer | B2: 0.15
A3: Target USD per month | B3: =B1*(1+B2)*B6
A4: Source: chat 1, 2026-08-07. Threshold rises with the SMI each year; update B1 when the 2027 figure is published.
A6: EUR to USD rate used for target | B6: 1.144
A7: Rate source: chat 1, 2026-08-07. Update to the current ECB rate.
A9: Month | B9: Gross deposits USD | C9: EUR at month-end rate | D9: Rate used | E9: Above threshold | F9: Non-Spain share | G9: Notes
A10: 46296 | B10: 6000 | C10: =IF(OR(B10="",D10=""),"",B10/D10) | D10: 1.144 | E10: =IF(C10="","",IF(C10>=$B$1,"Yes","No")) | F10: 1 | G10: Example values. Replace with real October deposits.
A11: 46327 | C11: =IF(OR(B11="",D11=""),"",B11/D11) | E11: =IF(C11="","",IF(C11>=$B$1,"Yes","No"))
A12: 46357 | C12: =IF(OR(B12="",D12=""),"",B12/D12) | E12: =IF(C12="","",IF(C12>=$B$1,"Yes","No"))
A13: 46388 | C13: =IF(OR(B13="",D13=""),"",B13/D13) | E13: =IF(C13="","",IF(C13>=$B$1,"Yes","No"))
A14: 46419 | C14: =IF(OR(B14="",D14=""),"",B14/D14) | E14: =IF(C14="","",IF(C14>=$B$1,"Yes","No"))
A15: 46447 | C15: =IF(OR(B15="",D15=""),"",B15/D15) | E15: =IF(C15="","",IF(C15>=$B$1,"Yes","No"))
A16: 46478 | C16: =IF(OR(B16="",D16=""),"",B16/D16) | E16: =IF(C16="","",IF(C16>=$B$1,"Yes","No"))
A17: 46508 | C17: =IF(OR(B17="",D17=""),"",B17/D17) | E17: =IF(C17="","",IF(C17>=$B$1,"Yes","No"))
A18: 46539 | C18: =IF(OR(B18="",D18=""),"",B18/D18) | E18: =IF(C18="","",IF(C18>=$B$1,"Yes","No"))
A19: 46569 | C19: =IF(OR(B19="",D19=""),"",B19/D19) | E19: =IF(C19="","",IF(C19>=$B$1,"Yes","No"))
A20: 46600 | C20: =IF(OR(B20="",D20=""),"",B20/D20) | E20: =IF(C20="","",IF(C20>=$B$1,"Yes","No"))
A21: 46631 | C21: =IF(OR(B21="",D21=""),"",B21/D21) | E21: =IF(C21="","",IF(C21>=$B$1,"Yes","No"))
A22: 46661 | C22: =IF(OR(B22="",D22=""),"",B22/D22) | E22: =IF(C22="","",IF(C22>=$B$1,"Yes","No"))
... A24: 46722 | C24: =IF(OR(B24="",D24=""),"",B24/D24) | E24: =IF(C24="","",IF(C24>=$B$1,"Yes","No"))

Sheet How to use
A1: Spain 2027 relocation and program plan
A3: Sheets
A4: Summary: counts of open, overdue, and due-soon items. Formulas, do not edit.
A5: Deadlines: every dated item. Edit the yellow Status and Notes columns. Days left and highlighting update automatically: red is overdue, yellow is due within 14 days.
A6: Monthly actions: the action items for each month. Edit Status and Notes.
A7: Programs: the program tracker. Edit Status, Deadline, Missing items.
A8: Income log: enter each month's gross deposits and the rate used. The sheet shows whether the month clears the visa threshold. The first row is an example, replace it.
A10: Yellow cells are for you to edit. Everything else is either source data or a formula.
A11: Dates marked Month only had no exact day in the source; the day is set to the 1st.
A12: Confidence column: Confirmed means verified with the source on the date shown. Assumed means inferred and needs checking. Not verified means unknown.
A14: Regenerating: this file is built from the markdown plan files in the spain2027 repo by scripts/build_plan_xlsx.py. If you edit here and also want the repo updated, share the edited file back.
A15: Built 2026-09-16
